Workbook
Name Bearish_ADX: Lists!$B$80:$B$83
Name Bearish_ADX_Moving_Average: Lists!$B$85:$B$85
Name Bearish_Alligator: Lists!$B$199:$B$203
Name Bearish_Aroon_Down: Lists!$B$292:$B$293
Name Bearish_Aroon_Oscillator: Lists!$B$105:$B$106
Name Bearish_ATR: Lists!$B$241:$B$242
Name Bearish_ATR_Bands: Lists!$B$244:$B$251
Name Bearish_ATR_Trailing_Stoploss: Lists!$B$180:$B$181
Name Bearish_Awesome_Oscillator: Lists!$B$253:$B$255
Name Bearish_Bollinger_Bandwidth: Lists!$B$257:$B$258
Name Bearish_Bollinger_pctB: Lists!$B$298:$B$299
Name Bearish_CCI: Lists!$B$114:$B$116
Name Bearish_Chaikin_Money_Flow: Lists!$B$260:$B$261
Name Bearish_Chande_Momentum_Oscillator: Lists!$B$263:$B$265
Name Bearish_Choppiness_Index: Lists!$B$233:$B$234
Name Bearish_Close: Lists!$B$183:$B$189
Name Bearish_Coppock_Curve: Lists!$B$339:$B$340
Name Bearish_DEMA: Lists!$B$34:$B$45
Name Bearish_Donchian_Channel: Lists!$B$205:$B$208
Name Bearish_Ehler_Fisher: Lists!$B$336:$B$337
Name Bearish_Elder_Force_Index: Lists!$B$267:$B$269
Name Bearish_EMA: Lists!$B$21:$B$32
Name Bearish_Fractal_Chaos_Bands: Lists!$B$320:$B$321
Name Bearish_Ichimoku_Cloud: Lists!$B$236:$B$239
Name Bearish_Keltner_Channel: Lists!$B$210:$B$213
Name Bearish_Linear_Regression_Forecast: Lists!$B$289:$B$290
Name Bearish_Low: Lists!$B$196:$B$197
Name Bearish_MACD: Lists!$B$274:$B$278
Name Bearish_Median_Price: Lists!$B$175:$B$176
Name Bearish_Median_Price_Moving_Average: Lists!$B$178:$B$178
Name Bearish_MFI_Moving_Average: Lists!$B$137:$B$137
Name Bearish_Middle_Bollinger_Bands: Lists!$B$99:$B$100
Name Bearish_minusDI: Lists!$B$283:$B$284
Name Bearish_Momentum_Indicator: Lists!$B$313:$B$314
Name Bearish_Money_Flow_Index: Lists!$B$131:$B$135
Name Bearish_Moving_Average: Lists!$B$67:$B$78
Name Bearish_Nth_Candle: Lists!$B$155:$B$159
Name Bearish_OBV: Lists!$B$129:$B$129
Name Bearish_OBV_Moving_Average: Lists!$B$331:$B$334
Name Bearish_Open: Lists!$B$194:$B$194
Name Bearish_Opening_Range: Lists!$B$148:$B$153
Name Bearish_Parabolic_SAR: Lists!$B$304:$B$305
Name Bearish_Pivot_Points: Lists!$B$161:$B$168
Name Bearish_plusDI: Lists!$B$280:$B$281
Name Bearish_Previous_N: Lists!$B$139:$B$146
Name Bearish_Price_Rate_Of_Change: Lists!$B$316:$B$318
Name Bearish_RSI: Lists!$B$13:$B$16
Name Bearish_RSI_Moving_Average: Lists!$B$19:$B$19
Name Bearish_SMA: Lists!$B$2:$B$11
Name Bearish_Standard_Deviation: Lists!$B$286:$B$287
Name Bearish_Stochastic: Lists!$B$118:$B$122
Name Bearish_Stochastic_RSI: Lists!$B$47:$B$52
Name Bearish_Supertrend: Lists!$B$87:$B$88
Name Bearish_Swing_Index: Lists!$B$325:$B$326
Name Bearish_TEMA: Lists!$B$54:$B$65
Name Bearish_Time_Series_Forecast: Lists!$B$342:$B$343
Name Bearish_Trend_Intensity_Index: Lists!$B$307:$B$309
Name Bearish_True_Range: Lists!$B$301:$B$302
Name Bearish_Twiggs_Money_Flow: Lists!$B$328:$B$329
Name Bearish_Ultimate_Oscillator: Lists!$B$271:$B$272

Sheet Lists
A1: Indicator | B1: Bearish Suggestion | C1: Tag | D1: Bullish Suggestion | E1: Tag | G1: Suggestion | H1: Tag | J1: Categories
A2: SMA | B2: SMA(close, 9, 0) crosses below SMA(close, 21, 0) | C2: Scalping | D2: SMA(close, 9, 0) crosses above SMA(close, 21, 0) | E2: Scalping | G2: SMA(close, 9, 0) crosses below SMA(close, 21, 0) | H2: Scalping | J2: Scalping
B3: SMA(close, 5, 0) crosses below SMA(close, 20, 0) | C3: Scalping | D3: SMA(close, 5, 0) crosses above SMA(close, 20, 0) | E3: Scalping | G3: SMA(close, 9, 0) crosses above SMA(close, 21, 0) | H3: Scalping | J3: Trend Following
B4: SMA(close, 21, 0) crosses above Close(0) | C4: Scalping | D4: Close(0) crosses above SMA(close, 21, 0) | E4: Scalping | G4: SMA(close, 5, 0) crosses below SMA(close, 20, 0) | H4: Scalping | J4: Long-term
B5: SMA(close, 20, 0) crosses below SMA(close, 50, 0) | C5: Trend Following | D5: SMA(close, 20, 0) crosses above SMA(close, 50, 0) | E5: Trend Following | G5: SMA(close, 5, 0) crosses above SMA(close, 20, 0) | H5: Scalping | J5: Trend Reversal
B6: SMA(close, 50, 0) crosses below SMA(close, 100, 0) | C6: Trend Following | D6: SMA(close, 50, 0) crosses above SMA(close, 100, 0) | E6: Trend Following | G6: SMA(close, 21, 0) crosses above Close(0) | H6: Scalping
B7: SMA(close, 50, 0) crosses below SMA(close, 200, 0) | C7: Trend Following | D7: SMA(close, 50, 0) crosses above SMA(close, 200, 0) | E7: Trend Following | G7: Close(0) crosses above SMA(close, 21, 0) | H7: Scalping
B8: SMA(close, 100, 0) crosses below SMA(close, 200, 0) | C8: Long-term | D8: SMA(close, 100, 0) crosses above SMA(close, 200, 0) | E8: Long-term | G8: SMA(close, 20, 0) crosses below SMA(close, 50, 0) | H8: Trend Following
B9: SMA(close, 9, 0) lower than SMA(close, 21, 0) | C9: Long-term | D9: SMA(close, 9, 0) higher than SMA(close, 21, 0) | E9: Long-term | G9: SMA(close, 20, 0) crosses above SMA(close, 50, 0) | H9: Trend Following
B10: SMA(close, 20, 0) lower than SMA(close, 50, 0) | C10: Trend Reversal | D10: SMA(close, 20, 0) higher than SMA(close, 50, 0) | E10: Trend Reversal | G10: SMA(close, 50, 0) crosses below SMA(close, 100, 0) | H10: Trend Following
B11: SMA(close, 50, 0) lower than SMA(close, 200, 0) | C11: Trend Reversal | D11: SMA(close, 50, 0) higher than SMA(close, 200, 0) | E11: Trend Reversal | G11: SMA(close, 50, 0) crosses above SMA(close, 100, 0) | H11: Trend Following
G12: SMA(close, 50, 0) crosses below SMA(close, 200, 0) | H12: Trend Following
A13: RSI | B13: RSI(14,0) crosses below 50 | C13: Oscillator | D13: RSI(14,0) crosses above 30 | E13: Oscillator | G13: SMA(close, 50, 0) crosses above SMA(close, 200, 0) | H13: Trend Following
B14: RSI(14,0) lower than RSI(14,-1) | C14: Oscillator | D14: RSI(14,0) crosses above 50 | E14: Oscillator | G14: SMA(close, 100, 0) crosses below SMA(close, 200, 0) | H14: Long-term
B15: RSI(14,0) crosses below RSI MA(14,simple,20,0) | C15: Oscillator | D15: RSI(14,0) higher than RSI(14,-1) | E15: Oscillator | G15: SMA(close, 100, 0) crosses above SMA(close, 200, 0) | H15: Long-term
B16: RSI(14,0) lower than RSI MA(14,simple,20,0) | C16: Oscillator | D16: RSI(14,0) crosses above RSI MA(14,simple,20,0) | E16: Oscillator | G16: SMA(close, 9, 0) lower than SMA(close, 21, 0) | H16: Long-term
D17: RSI(14,0) higher than RSI MA(14,simple,20,0) | E17: Oscillator | G17: SMA(close, 9, 0) higher than SMA(close, 21, 0) | H17: Long-term
G18: SMA(close, 20, 0) lower than SMA(close, 50, 0) | H18: Trend Reversal
A19: RSI Moving Average | B19: RSI MA(14,simple,20,0) crosses below RSI MA(14,simple,40,0) | C19: Oscillator | D19: RSI MA(14,simple,20,0) crosses above RSI MA(14,simple,40,0) | E19: Oscillator | G19: SMA(close, 20, 0) higher than SMA(close, 50, 0) | H19: Trend Reversal
G20: SMA(close, 50, 0) lower than SMA(close, 200, 0) | H20: Trend Reversal
A21: EMA | B21: EMA(close,9,0) crosses below EMA(close,21,0) | C21: Short-Term Bearish Crossover | D21: EMA(close,9,0) crosses above EMA(close,21,0) | E21: Short-Term Bullish Crossover | G21: SMA(close, 50, 0) higher than SMA(close, 200, 0) | H21: Trend Reversal
B22: EMA(close,5,0) crosses below EMA(close,20,0) | C22: Fast EMA Bearish Crossover | D22: EMA(close,5,0) crosses above EMA(close,20,0) | E22: Fast EMA Bullish Crossover | G22: RSI(14,0) crosses below 50 | H22: Oscillator
B23: EMA(close,21,0) crosses above Close(0) | C23: Price Breakdown | D23: EMA(close,21,0) crosses below Close(0) | E23: Price Breakout | G23: RSI(14,0) crosses above 30 | H23: Oscillator
B24: EMA(close,20,0) crosses below EMA(close,50,0) | C24: Bearish Crossover | D24: EMA(close,20,0) crosses above EMA(close,50,0) | E24: Trend Strengthening | G24: RSI(14,0) lower than RSI(14,-1) | H24: Oscillator
B25: EMA(close,50,0) crosses below EMA(close,100,0) | C25: Momentum Breakdown | D25: EMA(close,50,0) crosses above EMA(close,100,0) | E25: Momentum Build-Up | G25: RSI(14,0) crosses above 50 | H25: Oscillator
B26: EMA(close,50,0) crosses below EMA(close,200,0) | C26: Death Cross | D26: EMA(close,50,0) crosses above EMA(close,200,0) | E26: Golden Cross | G26: RSI(14,0) crosses below RSI MA(14,simple,20,0) | H26: Oscillator
B27: EMA(close,100,0) crosses below EMA(close,200,0) | C27: Slow EMA Bearish Crossover | D27: EMA(close,100,0) crosses above EMA(close,200,0) | E27: Trend Strengthening | G27: RSI(14,0) higher than RSI(14,-1) | H27: Oscillator
B28: EMA(close,9,0) lower than EMA(close,21,0) | C28: Short-Term Bearish Bias | D28: EMA(close,9,0) higher than EMA(close,21,0) | E28: Short-Term Uptrend Holding | G28: RSI(14,0) lower than RSI MA(14,simple,20,0) | H28: Oscillator
B29: EMA(close,50,0) crosses above Close(0) | C29: Bearish Breakdown | D29: EMA(close,50,0) crosses below Close(0) | E29: Mid-Term Breakout | G29: RSI(14,0) crosses above RSI MA(14,simple,20,0) | H29: Oscillator
B30: EMA(close,20,0) lower than EMA(close,50,0) | C30: Down Trend Pressure | D30: EMA(close,20,0) higher than EMA(close,50,0) | E30: Trend Direction Up | G30: RSI(14,0) higher than RSI MA(14,simple,20,0) | H30: Oscillator
B31: EMA(close,200,0) crosses above Close(0) | C31: Strong Bearish Bias | D31: EMA(close,200,0) crosses below Close(0) | E31: Long-Term Breakout | G31: RSI MA(14,simple,20,0) crosses below RSI MA(14,simple,40,0) | H31: Oscillator
B32: EMA(close,50,0) lower than EMA(close,200,0) | C32: Bearish Alignment | D32: EMA(close,50,0) higher than EMA(close,200,0) | E32: Bullish Alignment | G32: RSI MA(14,simple,20,0) crosses above RSI MA(14,simple,40,0) | H32: Oscillator
G33: EMA(close,9,0) crosses below EMA(close,21,0) | H33: Short-Term Bearish Crossover
A34: DEMA | B34: DEMA(close,9,0) crosses below DEMA(close,21,0) | C34: Bearish Crossover | D34: DEMA(close,9,0) crosses above DEMA(close,21,0) | E34: Trend Reversal | G34: EMA(close,9,0) crosses above EMA(close,21,0) | H34: Short-Term Bullish Crossover
B35: DEMA(close,5,0) crosses below DEMA(close,20,0) | C35: Fast Momentum Drop | D35: DEMA(close,5,0) crosses above DEMA(close,20,0) | E35: Fast Momentum | G35: EMA(close,5,0) crosses below EMA(close,20,0) | H35: Fast EMA Bearish Crossover
B36: DEMA(close,21,0) crosses above Close(0) | C36: Bearish Confirmation | D36: DEMA(close,21,0) crosses below Close(0) | E36: Breakout Confirmation | G36: EMA(close,5,0) crosses above EMA(close,20,0) | H36: Fast EMA Bullish Crossover
B37: DEMA(close,20,0) crosses below DEMA(close,50,0) | C37: Bearish Trend Start | D37: DEMA(close,20,0) crosses above DEMA(close,50,0) | E37: Bullish Trend Start | G37: EMA(close,21,0) crosses above Close(0) | H37: Price Breakdown
B38: DEMA(close,50,0) crosses below DEMA(close,100,0) | C38: Trend Reversal | D38: DEMA(close,50,0) crosses above DEMA(close,100,0) | E38: Momentum Shift | G38: EMA(close,21,0) crosses below Close(0) | H38: Price Breakout
B39: DEMA(close,50,0) crosses below DEMA(close,200,0) | C39: Death Cross | D39: DEMA(close,50,0) crosses above DEMA(close,200,0) | E39: Golden Crossover | G39: EMA(close,20,0) crosses below EMA(close,50,0) | H39: Bearish Crossover
B40: DEMA(close,100,0) crosses below DEMA(close,200,0) | C40: Trend Weakness | D40: DEMA(close,100,0) crosses above DEMA(close,200,0) | E40: Bullish Signal | G40: EMA(close,20,0) crosses above EMA(close,50,0) | H40: Trend Strengthening
...

Sheet Indicators
A1: Indicator Name | B1: Supported Condition Operators | C1: Bearish Suggestion | D1: Tag | E1: Bias | F1: Bullish Suggestion | G1: Tag | H1: Bias
A2: SMA | B2: Equal To | Crosses Above | Crosses Below | Higher Than | Lower Than | Higher Than Equal To | Lower Than Equal To | Up By % | Down By % | C2: SMA(close, 5, 0) crosses below SMA(close, 20, 0) | D2: =IF(C2="","",VLOOKUP(C2,Lists!$G$2:$H$531,2,FALSE)) -> Scalping | E2: =IF(C2="","","Bearish") -> Bearish | F2: SMA(close, 50, 0) crosses above SMA(close, 100, 0) | G2: =IF(F2="","",VLOOKUP(F2,Lists!$G$2:$H$531,2,FALSE)) -> Trend Following | H2: =IF(F2="","","Bullish") -> Bullish
A3: RSI | B3: Equal To | Crosses Above | Crosses Below | Higher Than | Lower Than | Higher Than Equal To | Lower Than Equal To | Up By % | Down By % | D3: =IF(C3="","",VLOOKUP(C3,Lists!$G$2:$H$531,2,FALSE)) | E3: =IF(C3="","","Bearish") | G3: =IF(F3="","",VLOOKUP(F3,Lists!$G$2:$H$531,2,FALSE)) | H3: =IF(F3="","","Bullish")
A4: RSI Moving Average | B4: Equal To | Crosses Above | Crosses Below | Higher Than | Lower Than | Higher Than Equal To | Lower Than Equal To | Up By % | Down By % | D4: =IF(C4="","",VLOOKUP(C4,Lists!$G$2:$H$531,2,FALSE)) | E4: =IF(C4="","","Bearish") | G4: =IF(F4="","",VLOOKUP(F4,Lists!$G$2:$H$531,2,FALSE)) | H4: =IF(F4="","","Bullish")
A5: EMA | B5: Equal To | Crosses Above | Crosses Below | Higher Than | Lower Than | Higher Than Equal To | Lower Than Equal To | Up By % | Down By % | D5: =IF(C5="","",VLOOKUP(C5,Lists!$G$2:$H$531,2,FALSE)) | E5: =IF(C5="","","Bearish") | G5: =IF(F5="","",VLOOKUP(F5,Lists!$G$2:$H$531,2,FALSE)) | H5: =IF(F5="","","Bullish")
A6: WMA | B6: Equal To | Crosses Above | Crosses Below | Higher Than | Lower Than | Higher Than Equal To | Lower Than Equal To | Up By % | Down By %
A7: DEMA | B7: Equal To | Crosses Above | Crosses Below | Higher Than | Lower Than | Higher Than Equal To | Lower Than Equal To | Up By % | Down By % | D7: =IF(C7="","",VLOOKUP(C7,Lists!$G$2:$H$531,2,FALSE)) | E7: =IF(C7="","","Bearish") | G7: =IF(F7="","",VLOOKUP(F7,Lists!$G$2:$H$531,2,FALSE)) | H7: =IF(F7="","","Bullish")
A8: TEMA | B8: Equal To | Crosses Above | Crosses Below | Higher Than | Lower Than | Higher Than Equal To | Lower Than Equal To | Up By % | Down By % | D8: =IF(C8="","",VLOOKUP(C8,Lists!$G$2:$H$531,2,FALSE)) | E8: =IF(C8="","","Bearish") | G8: =IF(F8="","",VLOOKUP(F8,Lists!$G$2:$H$531,2,FALSE)) | H8: =IF(F8="","","Bullish")
A9: Moving Average | B9: Equal To | Crosses Above | Crosses Below | Higher Than | Lower Than | Higher Than Equal To | Lower Than Equal To | Up By % | Down By % | D9: =IF(C9="","",VLOOKUP(C9,Lists!$G$2:$H$531,2,FALSE)) | E9: =IF(C9="","","Bearish") | G9: =IF(F9="","",VLOOKUP(F9,Lists!$G$2:$H$531,2,FALSE)) | H9: =IF(F9="","","Bullish")
A10: ADX | B10: Equal To | Crosses Above | Crosses Below | Higher Than | Lower Than | Higher Than Equal To | Lower Than Equal To | Up By % | Down By % | D10: =IF(C10="","",VLOOKUP(C10,Lists!$G$2:$H$531,2,FALSE)) | E10: =IF(C10="","","Bearish") | G10: =IF(F10="","",VLOOKUP(F10,Lists!$G$2:$H$531,2,FALSE)) | H10: =IF(F10="","","Bullish")
A11: ADX Moving Average | B11: Equal To | Crosses Above | Crosses Below | Higher Than | Lower Than | Higher Than Equal To | Lower Than Equal To | Up By % | Down By % | D11: =IF(C11="","",VLOOKUP(C11,Lists!$G$2:$H$531,2,FALSE)) | E11: =IF(C11="","","Bearish") | G11: =IF(F11="","",VLOOKUP(F11,Lists!$G$2:$H$531,2,FALSE)) | H11: =IF(F11="","","Bullish")
A12: Supertrend | B12: Equal To | Crosses Above | Crosses Below | Higher Than | Lower Than | Higher Than Equal To | Lower Than Equal To | Up By % | Down By % | D12: =IF(C12="","",VLOOKUP(C12,Lists!$G$2:$H$531,2,FALSE)) | E12: =IF(C12="","","Bearish") | G12: =IF(F12="","",VLOOKUP(F12,Lists!$G$2:$H$531,2,FALSE)) | H12: =IF(F12="","","Bullish")
A13: Williams %R | B13: Equal To | Crosses Above | Crosses Below | Higher Than | Lower Than | Higher Than Equal To | Lower Than Equal To | Up By % | Down By % | D13: =IF(C13="","",VLOOKUP(C13,Lists!$G$2:$H$531,2,FALSE)) | E13: =IF(C13="","","Bearish") | G13: =IF(F13="","",VLOOKUP(F13,Lists!$G$2:$H$531,2,FALSE)) | H13: =IF(F13="","","Bullish")
A14: Lower Bollinger Bands | B14: Equal To | Crosses Above | Crosses Below | Higher Than | Lower Than | Higher Than Equal To | Lower Than Equal To | Up By % | Down By % | D14: =IF(C14="","",VLOOKUP(C14,Lists!$G$2:$H$531,2,FALSE)) | E14: =IF(C14="","","Bearish") | G14: =IF(F14="","",VLOOKUP(F14,Lists!$G$2:$H$531,2,FALSE)) | H14: =IF(F14="","","Bullish")
A15: Middle Bollinger Bands | B15: Equal To | Crosses Above | Crosses Below | Higher Than | Lower Than | Higher Than Equal To | Lower Than Equal To | Up By % | Down By % | D15: =IF(C15="","",VLOOKUP(C15,Lists!$G$2:$H$531,2,FALSE)) | E15: =IF(C15="","","Bearish") | G15: =IF(F15="","",VLOOKUP(F15,Lists!$G$2:$H$531,2,FALSE)) | H15: =IF(F15="","","Bullish")
A16: Upper Bollinger Bands | B16: Equal To | Crosses Above | Crosses Below | Higher Than | Lower Than | Higher Than Equal To | Lower Than Equal To | Up By % | Down By % | D16: =IF(C16="","",VLOOKUP(C16,Lists!$G$2:$H$531,2,FALSE)) | E16: =IF(C16="","","Bearish") | G16: =IF(F16="","",VLOOKUP(F16,Lists!$G$2:$H$531,2,FALSE)) | H16: =IF(F16="","","Bullish")
A17: Aroon Oscillator | B17: Equal To | Crosses Above | Crosses Below | Higher Than | Lower Than | Higher Than Equal To | Lower Than Equal To | Up By % | Down By % | D17: =IF(C17="","",VLOOKUP(C17,Lists!$G$2:$H$531,2,FALSE)) | E17: =IF(C17="","","Bearish") | G17: =IF(F17="","",VLOOKUP(F17,Lists!$G$2:$H$531,2,FALSE)) | H17: =IF(F17="","","Bullish")
A18: VWAP | B18: Equal To | Crosses Above | Crosses Below | Higher Than | Lower Than | Higher Than Equal To | Lower Than Equal To | Up By % | Down By % | D18: =IF(C18="","",VLOOKUP(C18,Lists!$G$2:$H$531,2,FALSE)) | E18: =IF(C18="","","Bearish") | G18: =IF(F18="","",VLOOKUP(F18,Lists!$G$2:$H$531,2,FALSE)) | H18: =IF(F18="","","Bullish")
... A72: ATR Bands | B72: Equal To | Crosses Above | Crosses Below | Higher Than | Lower Than | Higher Than Equal To | Lower Than Equal To | Up By % | Down By % | D72: =IF(C72="","",VLOOKUP(C72,Lists!$G$2:$H$531,2,FALSE)) | E72: =IF(C72="","","Bearish") | G72: =IF(F72="","",VLOOKUP(F72,Lists!$G$2:$H$531,2,FALSE)) | H72: =IF(F72="","","Bullish")
